Workbook

Sheet Deliveries 1
K1: =IFERROR(__xludf.DUMMYFUNCTION("transpose(split(K3,"",""))"),"Canada") -> Canada | L1: =IFERROR(__xludf.DUMMYFUNCTION("transpose(split(L3,"",""))"),"Canada") -> Canada | M1: =IFERROR(__xludf.DUMMYFUNCTION("transpose(split(M3,"",""))"),"Canada") -> Canada | N1: =IFERROR(__xludf.DUMMYFUNCTION("transpose(split(N3,"",""))"),"Canada") -> Canada | O1: =IFERROR(__xludf.DUMMYFUNCTION("transpose(split(O3,"",""))"),"China") -> China | P1: =IFERROR(__xludf.DUMMYFUNCTION("transpose(split(P3,"",""))"),"China") -> China | Q1: =IFERROR(__xludf.DUMMYFUNCTION("transpose(split(Q3,"",""))"),"China") -> China | R1: =IFERROR(__xludf.DUMMYFUNCTION("transpose(split(R3,"",""))"),"Europe") -> Europe | S1: =IFERROR(__xludf.DUMMYFUNCTION("transpose(split(S3,"",""))"),"Europe") -> Europe | T1: =IFERROR(__xludf.DUMMYFUNCTION("transpose(split(T3,"",""))"),"Europe") -> Europe | U1: =IFERROR(__xludf.DUMMYFUNCTION("transpose(split(U3,"",""))"),"ROW") -> ROW | V1: =IFERROR(__xludf.DUMMYFUNCTION("transpose(split(V3,"",""))"),"ROW") -> ROW | W1: =IFERROR(__xludf.DUMMYFUNCTION("transpose(split(W3,"",""))"),"ROW") -> ROW | X1: =IFERROR(__xludf.DUMMYFUNCTION("transpose(split(X3,"",""))"),"ROW") -> ROW | Y1: =IFERROR(__xludf.DUMMYFUNCTION("transpose(split(Y3,"",""))"),"USA") -> USA | Z1: =IFERROR(__xludf.DUMMYFUNCTION("transpose(split(Z3,"",""))"),"USA") -> USA | AA1: =IFERROR(__xludf.DUMMYFUNCTION("transpose(split(AA3,"",""))"),"USA") -> USA | AB1: =IFERROR(__xludf.DUMMYFUNCTION("transpose(split(AB3,"",""))"),"USA") -> USA | AC1: =IFERROR(__xludf.DUMMYFUNCTION("transpose(split(AC3,"",""))"),"Total") -> Total
B2: Deliveries | C2: =IFERROR(__xludf.DUMMYFUNCTION("transpose(split(C3,"",""))"),"Canada") -> Canada | D2: =IFERROR(__xludf.DUMMYFUNCTION("transpose(split(D3,"",""))"),"China") -> China | E2: =IFERROR(__xludf.DUMMYFUNCTION("transpose(split(E3,"",""))"),"Europe") -> Europe | F2: =IFERROR(__xludf.DUMMYFUNCTION("transpose(split(F3,"",""))"),"ROW") -> ROW | G2: =IFERROR(__xludf.DUMMYFUNCTION("transpose(split(G3,"",""))"),"USA") -> USA | H2: Total | J2: Deliveries | K2: =IFERROR(__xludf.DUMMYFUNCTION("""COMPUTED_VALUE"""),"Cybertruck") -> Cybertruck | L2: =IFERROR(__xludf.DUMMYFUNCTION("""COMPUTED_VALUE"""),"Model 3") -> Model 3 | M2: =IFERROR(__xludf.DUMMYFUNCTION("""COMPUTED_VALUE"""),"Model S/X") -> Model S/X | N2: =IFERROR(__xludf.DUMMYFUNCTION("""COMPUTED_VALUE"""),"Model Y") -> Model Y | O2: =IFERROR(__xludf.DUMMYFUNCTION("""COMPUTED_VALUE"""),"Model 3") -> Model 3 | P2: =IFERROR(__xludf.DUMMYFUNCTION("""COMPUTED_VALUE"""),"Model S/X") -> Model S/X | Q2: =IFERROR(__xludf.DUMMYFUNCTION("""COMPUTED_VALUE"""),"Model Y") -> Model Y | R2: =IFERROR(__xludf.DUMMYFUNCTION("""COMPUTED_VALUE"""),"Model 3") -> Model 3 | S2: =IFERROR(__xludf.DUMMYFUNCTION("""COMPUTED_VALUE"""),"Model S/X") -> Model S/X | T2: =IFERROR(__xludf.DUMMYFUNCTION("""COMPUTED_VALUE"""),"Model Y") -> Model Y | U2: =IFERROR(__xludf.DUMMYFUNCTION("""COMPUTED_VALUE"""),"Cybertruck") -> Cybertruck | V2: =IFERROR(__xludf.DUMMYFUNCTION("""COMPUTED_VALUE"""),"Model 3") -> Model 3 | W2: =IFERROR(__xludf.DUMMYFUNCTION("""COMPUTED_VALUE"""),"Model S/X") -> Model S/X | X2: =IFERROR(__xludf.DUMMYFUNCTION("""COMPUTED_VALUE"""),"Model Y") -> Model Y | Y2: =IFERROR(__xludf.DUMMYFUNCTION("""COMPUTED_VALUE"""),"Cybertruck") -> Cybertruck | Z2: =IFERROR(__xludf.DUMMYFUNCTION("""COMPUTED_VALUE"""),"Model 3") -> Model 3 | AA2: =IFERROR(__xludf.DUMMYFUNCTION("""COMPUTED_VALUE"""),"Model S/X") -> Model S/X | AB2: =IFERROR(__xludf.DUMMYFUNCTION("""COMPUTED_VALUE"""),"Model Y") -> Model Y | AC2: All models
B3: =IFERROR(__xludf.DUMMYFUNCTION("{query({Delivery_Data!$A:$I},""select Col1,sum(Col8) where Col1 is not null and Col8 is not null group by Col1 pivot Col6"",1);index(query({Delivery_Data!$A:$I},""select 'Total',sum(Col8) where Col1 is not null and Col8 is not null pivot Col6"",1),2,0)}"),"Year") -> Year | C3: =IFERROR(__xludf.DUMMYFUNCTION("""COMPUTED_VALUE"""),"Canada") -> Canada | D3: =IFERROR(__xludf.DUMMYFUNCTION("""COMPUTED_VALUE"""),"China") -> China | E3: =IFERROR(__xludf.DUMMYFUNCTION("""COMPUTED_VALUE"""),"Europe") -> Europe | F3: =IFERROR(__xludf.DUMMYFUNCTION("""COMPUTED_VALUE"""),"ROW") -> ROW | G3: =IFERROR(__xludf.DUMMYFUNCTION("""COMPUTED_VALUE"""),"USA") -> USA | H3: {={"Total";if($B4:$B18="",,mmult(n($C$4:$G$18),transpose(sign(column($C$4:$G$18)))))}} -> Total | J3: =IFERROR(__xludf.DUMMYFUNCTION("{query({Delivery_Data!$A:$I},""select Col1,sum(Col8) where Col1 is not null and Col8 is not null group by Col1 pivot Col6,Col4"",1);index(query({Delivery_Data!$A:$I},""select 'Total',sum(Col8) where Col1 is not null and Col8 is not null pivot Col6,Col4"","&"1),2,0)}"),"Year") -> Year | K3: =IFERROR(__xludf.DUMMYFUNCTION("""COMPUTED_VALUE"""),"Canada,Cybertruck") -> Canada,Cybertruck | L3: =IFERROR(__xludf.DUMMYFUNCTION("""COMPUTED_VALUE"""),"Canada,Model 3") -> Canada,Model 3 | M3: =IFERROR(__xludf.DUMMYFUNCTION("""COMPUTED_VALUE"""),"Canada,Model S/X") -> Canada,Model S/X | N3: =IFERROR(__xludf.DUMMYFUNCTION("""COMPUTED_VALUE"""),"Canada,Model Y") -> Canada,Model Y | O3: =IFERROR(__xludf.DUMMYFUNCTION("""COMPUTED_VALUE"""),"China,Model 3") -> China,Model 3 | P3: =IFERROR(__xludf.DUMMYFUNCTION("""COMPUTED_VALUE"""),"China,Model S/X") -> China,Model S/X | Q3: =IFERROR(__xludf.DUMMYFUNCTION("""COMPUTED_VALUE"""),"China,Model Y") -> China,Model Y | R3: =IFERROR(__xludf.DUMMYFUNCTION("""COMPUTED_VALUE"""),"Europe,Model 3") -> Europe,Model 3 | S3: =IFERROR(__xludf.DUMMYFUNCTION("""COMPUTED_VALUE"""),"Europe,Model S/X") -> Europe,Model S/X | T3: =IFERROR(__xludf.DUMMYFUNCTION("""COMPUTED_VALUE"""),"Europe,Model Y") -> Europe,Model Y | U3: =IFERROR(__xludf.DUMMYFUNCTION("""COMPUTED_VALUE"""),"ROW,Cybertruck") -> ROW,Cybertruck | V3: =IFERROR(__xludf.DUMMYFUNCTION("""COMPUTED_VALUE"""),"ROW,Model 3") -> ROW,Model 3 | W3: =IFERROR(__xludf.DUMMYFUNCTION("""COMPUTED_VALUE"""),"ROW,Model S/X") -> ROW,Model S/X | X3: =IFERROR(__xludf.DUMMYFUNCTION("""COMPUTED_VALUE"""),"ROW,Model Y") -> ROW,Model Y | Y3: =IFERROR(__xludf.DUMMYFUNCTION("""COMPUTED_VALUE"""),"USA,Cybertruck") -> USA,Cybertruck | Z3: =IFERROR(__xludf.DUMMYFUNCTION("""COMPUTED_VALUE"""),"USA,Model 3") -> USA,Model 3 | AA3: =IFERROR(__xludf.DUMMYFUNCTION("""COMPUTED_VALUE"""),"USA,Model S/X") -> USA,Model S/X | AB3: =IFERROR(__xludf.DUMMYFUNCTION("""COMPUTED_VALUE"""),"USA,Model Y") -> USA,Model Y | AC3: {={"Total";if($J4:$J18="",,mmult(n($K$4:$AB$18),transpose(sign(column($K$4:$AB$18)))))}} -> Total
B4: =IFERROR(__xludf.DUMMYFUNCTION("""COMPUTED_VALUE"""),2012.0) -> 2012 | C4: =IFERROR(__xludf.DUMMYFUNCTION("""COMPUTED_VALUE"""),95.0) -> 95 | G4: =IFERROR(__xludf.DUMMYFUNCTION("""COMPUTED_VALUE"""),2555.0) -> 2555 | H4: 2650 | J4: =IFERROR(__xludf.DUMMYFUNCTION("""COMPUTED_VALUE"""),2012.0) -> 2012 | M4: =IFERROR(__xludf.DUMMYFUNCTION("""COMPUTED_VALUE"""),95.0) -> 95 | AA4: =IFERROR(__xludf.DUMMYFUNCTION("""COMPUTED_VALUE"""),2555.0) -> 2555 | AC4: 2650
B5: =IFERROR(__xludf.DUMMYFUNCTION("""COMPUTED_VALUE"""),2013.0) -> 2013 | C5: =IFERROR(__xludf.DUMMYFUNCTION("""COMPUTED_VALUE"""),638.0) -> 638 | E5: =IFERROR(__xludf.DUMMYFUNCTION("""COMPUTED_VALUE"""),3893.0) -> 3893 | G5: =IFERROR(__xludf.DUMMYFUNCTION("""COMPUTED_VALUE"""),17946.0) -> 17946 | H5: 22477 | J5: =IFERROR(__xludf.DUMMYFUNCTION("""COMPUTED_VALUE"""),2013.0) -> 2013 | M5: =IFERROR(__xludf.DUMMYFUNCTION("""COMPUTED_VALUE"""),638.0) -> 638 | S5: =IFERROR(__xludf.DUMMYFUNCTION("""COMPUTED_VALUE"""),3893.0) -> 3893 | AA5: =IFERROR(__xludf.DUMMYFUNCTION("""COMPUTED_VALUE"""),17946.0) -> 17946 | AC5: 22477
B6: =IFERROR(__xludf.DUMMYFUNCTION("""COMPUTED_VALUE"""),2014.0) -> 2014 | C6: =IFERROR(__xludf.DUMMYFUNCTION("""COMPUTED_VALUE"""),784.0) -> 784 | D6: =IFERROR(__xludf.DUMMYFUNCTION("""COMPUTED_VALUE"""),4122.0) -> 4122 | E6: =IFERROR(__xludf.DUMMYFUNCTION("""COMPUTED_VALUE"""),9521.0) -> 9521 | F6: =IFERROR(__xludf.DUMMYFUNCTION("""COMPUTED_VALUE"""),539.0) -> 539 | G6: =IFERROR(__xludf.DUMMYFUNCTION("""COMPUTED_VALUE"""),16689.0) -> 16689 | H6: 31655 | J6: =IFERROR(__xludf.DUMMYFUNCTION("""COMPUTED_VALUE"""),2014.0) -> 2014 | M6: =IFERROR(__xludf.DUMMYFUNCTION("""COMPUTED_VALUE"""),784.0) -> 784 | P6: =IFERROR(__xludf.DUMMYFUNCTION("""COMPUTED_VALUE"""),4122.0) -> 4122 | S6: =IFERROR(__xludf.DUMMYFUNCTION("""COMPUTED_VALUE"""),9521.0) -> 9521 | W6: =IFERROR(__xludf.DUMMYFUNCTION("""COMPUTED_VALUE"""),539.0) -> 539 | AA6: =IFERROR(__xludf.DUMMYFUNCTION("""COMPUTED_VALUE"""),16689.0) -> 16689 | AC6: 31655
B7: =IFERROR(__xludf.DUMMYFUNCTION("""COMPUTED_VALUE"""),2015.0) -> 2015 | C7: =IFERROR(__xludf.DUMMYFUNCTION("""COMPUTED_VALUE"""),1600.0) -> 1600 | D7: =IFERROR(__xludf.DUMMYFUNCTION("""COMPUTED_VALUE"""),3692.0) -> 3692 | E7: =IFERROR(__xludf.DUMMYFUNCTION("""COMPUTED_VALUE"""),16701.0) -> 16701 | F7: =IFERROR(__xludf.DUMMYFUNCTION("""COMPUTED_VALUE"""),3463.0) -> 3463 | G7: =IFERROR(__xludf.DUMMYFUNCTION("""COMPUTED_VALUE"""),25202.0) -> 25202 | H7: 50658 | J7: =IFERROR(__xludf.DUMMYFUNCTION("""COMPUTED_VALUE"""),2015.0) -> 2015 | M7: =IFERROR(__xludf.DUMMYFUNCTION("""COMPUTED_VALUE"""),1600.0) -> 1600 | P7: =IFERROR(__xludf.DUMMYFUNCTION("""COMPUTED_VALUE"""),3692.0) -> 3692 | S7: =IFERROR(__xludf.DUMMYFUNCTION("""COMPUTED_VALUE"""),16701.0) -> 16701 | W7: =IFERROR(__xludf.DUMMYFUNCTION("""COMPUTED_VALUE"""),3463.0) -> 3463 | AA7: =IFERROR(__xludf.DUMMYFUNCTION("""COMPUTED_VALUE"""),25202.0) -> 25202 | AC7: 50658
B8: =IFERROR(__xludf.DUMMYFUNCTION("""COMPUTED_VALUE"""),2016.0) -> 2016 | C8: =IFERROR(__xludf.DUMMYFUNCTION("""COMPUTED_VALUE"""),2283.0) -> 2283 | D8: =IFERROR(__xludf.DUMMYFUNCTION("""COMPUTED_VALUE"""),8377.0) -> 8377 | E8: =IFERROR(__xludf.DUMMYFUNCTION("""COMPUTED_VALUE"""),16230.0) -> 16230 | F8: =IFERROR(__xludf.DUMMYFUNCTION("""COMPUTED_VALUE"""),3660.0) -> 3660 | G8: =IFERROR(__xludf.DUMMYFUNCTION("""COMPUTED_VALUE"""),45735.0) -> 45735 | H8: 76285 | J8: =IFERROR(__xludf.DUMMYFUNCTION("""COMPUTED_VALUE"""),2016.0) -> 2016 | M8: =IFERROR(__xludf.DUMMYFUNCTION("""COMPUTED_VALUE"""),2283.0) -> 2283 | P8: =IFERROR(__xludf.DUMMYFUNCTION("""COMPUTED_VALUE"""),8377.0) -> 8377 | S8: =IFERROR(__xludf.DUMMYFUNCTION("""COMPUTED_VALUE"""),16230.0) -> 16230 | W8: =IFERROR(__xludf.DUMMYFUNCTION("""COMPUTED_VALUE"""),3660.0) -> 3660 | AA8: =IFERROR(__xludf.DUMMYFUNCTION("""COMPUTED_VALUE"""),45735.0) -> 45735 | AC8: 76285
B9: =IFERROR(__xludf.DUMMYFUNCTION("""COMPUTED_VALUE"""),2017.0) -> 2017 | C9: =IFERROR(__xludf.DUMMYFUNCTION("""COMPUTED_VALUE"""),2361.0) -> 2361 | D9: =IFERROR(__xludf.DUMMYFUNCTION("""COMPUTED_VALUE"""),14829.0) -> 14829 | E9: =IFERROR(__xludf.DUMMYFUNCTION("""COMPUTED_VALUE"""),28279.0) -> 28279 | F9: =IFERROR(__xludf.DUMMYFUNCTION("""COMPUTED_VALUE"""),7323.0) -> 7323 | G9: =IFERROR(__xludf.DUMMYFUNCTION("""COMPUTED_VALUE"""),50389.0) -> 50389 | H9: 103181 | J9: =IFERROR(__xludf.DUMMYFUNCTION("""COMPUTED_VALUE"""),2017.0) -> 2017 | M9: =IFERROR(__xludf.DUMMYFUNCTION("""COMPUTED_VALUE"""),2361.0) -> 2361 | P9: =IFERROR(__xludf.DUMMYFUNCTION("""COMPUTED_VALUE"""),14829.0) -> 14829 | S9: =IFERROR(__xludf.DUMMYFUNCTION("""COMPUTED_VALUE"""),28279.0) -> 28279 | W9: =IFERROR(__xludf.DUMMYFUNCTION("""COMPUTED_VALUE"""),7323.0) -> 7323 | Z9: =IFERROR(__xludf.DUMMYFUNCTION("""COMPUTED_VALUE"""),1764.0) -> 1764 | AA9: =IFERROR(__xludf.DUMMYFUNCTION("""COMPUTED_VALUE"""),48625.0) -> 48625 | AC9: 103181
B10: =IFERROR(__xludf.DUMMYFUNCTION("""COMPUTED_VALUE"""),2018.0) -> 2018 | C10: =IFERROR(__xludf.DUMMYFUNCTION("""COMPUTED_VALUE"""),7200.0) -> 7200 | D10: =IFERROR(__xludf.DUMMYFUNCTION("""COMPUTED_VALUE"""),15029.0) -> 15029 | E10: =IFERROR(__xludf.DUMMYFUNCTION("""COMPUTED_VALUE"""),29257.0) -> 29257 | F10: =IFERROR(__xludf.DUMMYFUNCTION("""COMPUTED_VALUE"""),3379.0) -> 3379 | G10: =IFERROR(__xludf.DUMMYFUNCTION("""COMPUTED_VALUE"""),190641.0) -> 190641 | H10: 245506 | J10: =IFERROR(__xludf.DUMMYFUNCTION("""COMPUTED_VALUE"""),2018.0) -> 2018 | L10: =IFERROR(__xludf.DUMMYFUNCTION("""COMPUTED_VALUE"""),4796.0) -> 4796 | M10: =IFERROR(__xludf.DUMMYFUNCTION("""COMPUTED_VALUE"""),2404.0) -> 2404 | P10: =IFERROR(__xludf.DUMMYFUNCTION("""COMPUTED_VALUE"""),15029.0) -> 15029 | S10: =IFERROR(__xludf.DUMMYFUNCTION("""COMPUTED_VALUE"""),29257.0) -> 29257 | W10: =IFERROR(__xludf.DUMMYFUNCTION("""COMPUTED_VALUE"""),3379.0) -> 3379 | Z10: =IFERROR(__xludf.DUMMYFUNCTION("""COMPUTED_VALUE"""),141259.0) -> 141259 | AA10: =IFERROR(__xludf.DUMMYFUNCTION("""COMPUTED_VALUE"""),49382.0) -> 49382 | AC10: 245506
B11: =IFERROR(__xludf.DUMMYFUNCTION("""COMPUTED_VALUE"""),2019.0) -> 2019 | C11: =IFERROR(__xludf.DUMMYFUNCTION("""COMPUTED_VALUE"""),15789.0) -> 15789 | D11: =IFERROR(__xludf.DUMMYFUNCTION("""COMPUTED_VALUE"""),41298.0) -> 41298 | E11: =IFERROR(__xludf.DUMMYFUNCTION("""COMPUTED_VALUE"""),111119.0) -> 111119 | F11: =IFERROR(__xludf.DUMMYFUNCTION("""COMPUTED_VALUE"""),11960.0) -> 11960 | G11: =IFERROR(__xludf.DUMMYFUNCTION("""COMPUTED_VALUE"""),187490.0) -> 187490 | H11: 367656 | J11: =IFERROR(__xludf.DUMMYFUNCTION("""COMPUTED_VALUE"""),2019.0) -> 2019 | L11: =IFERROR(__xludf.DUMMYFUNCTION("""COMPUTED_VALUE"""),14112.0) -> 14112 | M11: =IFERROR(__xludf.DUMMYFUNCTION("""COMPUTED_VALUE"""),1677.0) -> 1677 | O11: =IFERROR(__xludf.DUMMYFUNCTION("""COMPUTED_VALUE"""),29274.0) -> 29274 | P11: =IFERROR(__xludf.DUMMYFUNCTION("""COMPUTED_VALUE"""),12024.0) -> 12024 | R11: =IFERROR(__xludf.DUMMYFUNCTION("""COMPUTED_VALUE"""),95884.0) -> 95884 | S11: =IFERROR(__xludf.DUMMYFUNCTION("""COMPUTED_VALUE"""),15235.0) -> 15235 | V11: =IFERROR(__xludf.DUMMYFUNCTION("""COMPUTED_VALUE"""),8458.0) -> 8458 | W11: =IFERROR(__xludf.DUMMYFUNCTION("""COMPUTED_VALUE"""),3502.0) -> 3502 | Z11: =IFERROR(__xludf.DUMMYFUNCTION("""COMPUTED_VALUE"""),153157.0) -> 153157 | AA11: =IFERROR(__xludf.DUMMYFUNCTION("""COMPUTED_VALUE"""),34333.0) -> 34333 | AC11: 367656
B12: =IFERROR(__xludf.DUMMYFUNCTION("""COMPUTED_VALUE"""),2020.0) -> 2020 | C12: =IFERROR(__xludf.DUMMYFUNCTION("""COMPUTED_VALUE"""),18402.0) -> 18402 | D12: =IFERROR(__xludf.DUMMYFUNCTION("""COMPUTED_VALUE"""),146470.0) -> 146470 | E12: =IFERROR(__xludf.DUMMYFUNCTION("""COMPUTED_VALUE"""),99186.0) -> 99186 | F12: =IFERROR(__xludf.DUMMYFUNCTION("""COMPUTED_VALUE"""),27189.0) -> 27189 | G12: =IFERROR(__xludf.DUMMYFUNCTION("""COMPUTED_VALUE"""),208400.0) -> 208400 | H12: 499647 | J12: =IFERROR(__xludf.DUMMYFUNCTION("""COMPUTED_VALUE"""),2020.0) -> 2020 | L12: =IFERROR(__xludf.DUMMYFUNCTION("""COMPUTED_VALUE"""),14094.0) -> 14094 | M12: =IFERROR(__xludf.DUMMYFUNCTION("""COMPUTED_VALUE"""),1710.0) -> 1710 | N12: =IFERROR(__xludf.DUMMYFUNCTION("""COMPUTED_VALUE"""),2598.0) -> 2598 | O12: =IFERROR(__xludf.DUMMYFUNCTION("""COMPUTED_VALUE"""),139937.0) -> 139937 | P12: =IFERROR(__xludf.DUMMYFUNCTION("""COMPUTED_VALUE"""),6533.0) -> 6533 | R12: =IFERROR(__xludf.DUMMYFUNCTION("""COMPUTED_VALUE"""),87976.0) -> 87976 | S12: =IFERROR(__xludf.DUMMYFUNCTION("""COMPUTED_VALUE"""),11210.0) -> 11210 | V12: =IFERROR(__xludf.DUMMYFUNCTION("""COMPUTED_VALUE"""),24475.0) -> 24475 | W12: =IFERROR(__xludf.DUMMYFUNCTION("""COMPUTED_VALUE"""),2714.0) -> 2714 | Z12: =IFERROR(__xludf.DUMMYFUNCTION("""COMPUTED_VALUE"""),89768.0) -> 89768 | AA12: =IFERROR(__xludf.DUMMYFUNCTION("""COMPUTED_VALUE"""),34918.0) -> 34918 | AB12: =IFERROR(__xludf.DUMMYFUNCTION("""COMPUTED_VALUE"""),83714.0) -> 83714 | AC12: 499647
B13: =IFERROR(__xludf.DUMMYFUNCTION("""COMPUTED_VALUE"""),2021.0) -> 2021 | C13: =IFERROR(__xludf.DUMMYFUNCTION("""COMPUTED_VALUE"""),26369.0) -> 26369 | D13: =IFERROR(__xludf.DUMMYFUNCTION("""COMPUTED_VALUE"""),321270.0) -> 321270 | E13: =IFERROR(__xludf.DUMMYFUNCTION("""COMPUTED_VALUE"""),169351.0) -> 169351 | F13: =IFERROR(__xludf.DUMMYFUNCTION("""COMPUTED_VALUE"""),59227.0) -> 59227 | G13: =IFERROR(__xludf.DUMMYFUNCTION("""COMPUTED_VALUE"""),360005.0) -> 360005 | H13: 936222 | J13: =IFERROR(__xludf.DUMMYFUNCTION("""COMPUTED_VALUE"""),2021.0) -> 2021 | L13: =IFERROR(__xludf.DUMMYFUNCTION("""COMPUTED_VALUE"""),15602.0) -> 15602 | M13: =IFERROR(__xludf.DUMMYFUNCTION("""COMPUTED_VALUE"""),643.0) -> 643 | N13: =IFERROR(__xludf.DUMMYFUNCTION("""COMPUTED_VALUE"""),10124.0) -> 10124 | O13: =IFERROR(__xludf.DUMMYFUNCTION("""COMPUTED_VALUE"""),150890.0) -> 150890 | P13: =IFERROR(__xludf.DUMMYFUNCTION("""COMPUTED_VALUE"""),527.0) -> 527 | Q13: =IFERROR(__xludf.DUMMYFUNCTION("""COMPUTED_VALUE"""),169853.0) -> 169853 | R13: =IFERROR(__xludf.DUMMYFUNCTION("""COMPUTED_VALUE"""),143664.0) -> 143664 | S13: =IFERROR(__xludf.DUMMYFUNCTION("""COMPUTED_VALUE"""),310.0) -> 310 | T13: =IFERROR(__xludf.DUMMYFUNCTION("""COMPUTED_VALUE"""),25377.0) -> 25377 | V13: =IFERROR(__xludf.DUMMYFUNCTION("""COMPUTED_VALUE"""),47251.0) -> 47251 | W13: =IFERROR(__xludf.DUMMYFUNCTION("""COMPUTED_VALUE"""),103.0) -> 103 | X13: =IFERROR(__xludf.DUMMYFUNCTION("""COMPUTED_VALUE"""),11873.0) -> 11873 | Z13: =IFERROR(__xludf.DUMMYFUNCTION("""COMPUTED_VALUE"""),152777.0) -> 152777 | AA13: =IFERROR(__xludf.DUMMYFUNCTION("""COMPUTED_VALUE"""),23397.0) -> 23397 | AB13: =IFERROR(__xludf.DUMMYFUNCTION("""COMPUTED_VALUE"""),183831.0) -> 183831 | AC13: 936222
B14: =IFERROR(__xludf.DUMMYFUNCTION("""COMPUTED_VALUE"""),2022.0) -> 2022 | C14: =IFERROR(__xludf.DUMMYFUNCTION("""COMPUTED_VALUE"""),44390.0) -> 44390 | D14: =IFERROR(__xludf.DUMMYFUNCTION("""COMPUTED_VALUE"""),439770.0) -> 439770 | E14: =IFERROR(__xludf.DUMMYFUNCTION("""COMPUTED_VALUE"""),233964.0) -> 233964 | F14: =IFERROR(__xludf.DUMMYFUNCTION("""COMPUTED_VALUE"""),84675.0) -> 84675 | G14: =IFERROR(__xludf.DUMMYFUNCTION("""COMPUTED_VALUE"""),511052.0) -> 511052 | H14: 1313851 | J14: =IFERROR(__xludf.DUMMYFUNCTION("""COMPUTED_VALUE"""),2022.0) -> 2022 | L14: =IFERROR(__xludf.DUMMYFUNCTION("""COMPUTED_VALUE"""),24344.0) -> 24344 | M14: =IFERROR(__xludf.DUMMYFUNCTION("""COMPUTED_VALUE"""),3048.0) -> 3048 | N14: =IFERROR(__xludf.DUMMYFUNCTION("""COMPUTED_VALUE"""),16998.0) -> 16998 | O14: =IFERROR(__xludf.DUMMYFUNCTION("""COMPUTED_VALUE"""),124456.0) -> 124456 | P14: =IFERROR(__xludf.DUMMYFUNCTION("""COMPUTED_VALUE"""),0.0) -> 0 | Q14: =IFERROR(__xludf.DUMMYFUNCTION("""COMPUTED_VALUE"""),315314.0) -> 315314 | R14: =IFERROR(__xludf.DUMMYFUNCTION("""COMPUTED_VALUE"""),92356.0) -> 92356 | S14: =IFERROR(__xludf.DUMMYFUNCTION("""COMPUTED_VALUE"""),2911.0) -> 2911 | T14: =IFERROR(__xludf.DUMMYFUNCTION("""COMPUTED_VALUE"""),138697.0) -> 138697 | V14: =IFERROR(__xludf.DUMMYFUNCTION("""COMPUTED_VALUE"""),41253.0) -> 41253 | W14: =IFERROR(__xludf.DUMMYFUNCTION("""COMPUTED_VALUE"""),255.0) -> 255 | X14: =IFERROR(__xludf.DUMMYFUNCTION("""COMPUTED_VALUE"""),43167.0) -> 43167 | Z14: =IFERROR(__xludf.DUMMYFUNCTION("""COMPUTED_VALUE"""),199740.0) -> 199740 | AA14: =IFERROR(__xludf.DUMMYFUNCTION("""COMPUTED_VALUE"""),60491.0) -> 60491 | AB14: =IFERROR(__xludf.DUMMYFUNCTION("""COMPUTED_VALUE"""),250821.0) -> 250821 | AC14: 1313851
B15: =IFERROR(__xludf.DUMMYFUNCTION("""COMPUTED_VALUE"""),2023.0) -> 2023 | C15: =IFERROR(__xludf.DUMMYFUNCTION("""COMPUTED_VALUE"""),51222.0) -> 51222 | D15: =IFERROR(__xludf.DUMMYFUNCTION("""COMPUTED_VALUE"""),610685.0) -> 610685 | E15: =IFERROR(__xludf.DUMMYFUNCTION("""COMPUTED_VALUE"""),365171.0) -> 365171 | F15: =IFERROR(__xludf.DUMMYFUNCTION("""COMPUTED_VALUE"""),132864.0) -> 132864 | G15: =IFERROR(__xludf.DUMMYFUNCTION("""COMPUTED_VALUE"""),648639.0) -> 648639 | H15: 1808581 | J15: =IFERROR(__xludf.DUMMYFUNCTION("""COMPUTED_VALUE"""),2023.0) -> 2023 | L15: =IFERROR(__xludf.DUMMYFUNCTION("""COMPUTED_VALUE"""),18725.0) -> 18725 | M15: =IFERROR(__xludf.DUMMYFUNCTION("""COMPUTED_VALUE"""),2995.0) -> 2995 | N15: =IFERROR(__xludf.DUMMYFUNCTION("""COMPUTED_VALUE"""),29502.0) -> 29502 | O15: =IFERROR(__xludf.DUMMYFUNCTION("""COMPUTED_VALUE"""),147270.0) -> 147270 | P15: =IFERROR(__xludf.DUMMYFUNCTION("""COMPUTED_VALUE"""),7021.0) -> 7021 | Q15: =IFERROR(__xludf.DUMMYFUNCTION("""COMPUTED_VALUE"""),456394.0) -> 456394 | R15: =IFERROR(__xludf.DUMMYFUNCTION("""COMPUTED_VALUE"""),100932.0) -> 100932 | S15: =IFERROR(__xludf.DUMMYFUNCTION("""COMPUTED_VALUE"""),9054.0) -> 9054 | T15: =IFERROR(__xludf.DUMMYFUNCTION("""COMPUTED_VALUE"""),255185.0) -> 255185 | V15: =IFERROR(__xludf.DUMMYFUNCTION("""COMPUTED_VALUE"""),34437.0) -> 34437 | W15: =IFERROR(__xludf.DUMMYFUNCTION("""COMPUTED_VALUE"""),5198.0) -> 5198 | X15: =IFERROR(__xludf.DUMMYFUNCTION("""COMPUTED_VALUE"""),93229.0) -> 93229 | Y15: =IFERROR(__xludf.DUMMYFUNCTION("""COMPUTED_VALUE"""),124.0) -> 124 | Z15: =IFERROR(__xludf.DUMMYFUNCTION("""COMPUTED_VALUE"""),219000.0) -> 219000 | AA15: =IFERROR(__xludf.DUMMYFUNCTION("""COMPUTED_VALUE"""),44482.0) -> 44482 | AB15: =IFERROR(__xludf.DUMMYFUNCTION("""COMPUTED_VALUE"""),385033.0) -> 385033 | AC15: 1808581
B16: =IFERROR(__xludf.DUMMYFUNCTION("""COMPUTED_VALUE"""),2024.0) -> 2024 | C16: =IFERROR(__xludf.DUMMYFUNCTION("""COMPUTED_VALUE"""),45621.0) -> 45621 | D16: =IFERROR(__xludf.DUMMYFUNCTION("""COMPUTED_VALUE"""),659147.0) -> 659147 | E16: =IFERROR(__xludf.DUMMYFUNCTION("""COMPUTED_VALUE"""),325989.0) -> 325989 | F16: =IFERROR(__xludf.DUMMYFUNCTION("""COMPUTED_VALUE"""),138520.0) -> 138520 | G16: =IFERROR(__xludf.DUMMYFUNCTION("""COMPUTED_VALUE"""),619949.0) -> 619949 | H16: 1789226 | J16: =IFERROR(__xludf.DUMMYFUNCTION("""COMPUTED_VALUE"""),2024.0) -> 2024 | K16: =IFERROR(__xludf.DUMMYFUNCTION("""COMPUTED_VALUE"""),1540.0) -> 1540 | L16: =IFERROR(__xludf.DUMMYFUNCTION("""COMPUTED_VALUE"""),11215.0) -> 11215 | M16: =IFERROR(__xludf.DUMMYFUNCTION("""COMPUTED_VALUE"""),2690.0) -> 2690 | N16: =IFERROR(__xludf.DUMMYFUNCTION("""COMPUTED_VALUE"""),30176.0) -> 30176 | O16: =IFERROR(__xludf.DUMMYFUNCTION("""COMPUTED_VALUE"""),176793.0) -> 176793 | P16: =IFERROR(__xludf.DUMMYFUNCTION("""COMPUTED_VALUE"""),2045.0) -> 2045 | Q16: =IFERROR(__xludf.DUMMYFUNCTION("""COMPUTED_VALUE"""),480309.0) -> 480309 | R16: =IFERROR(__xludf.DUMMYFUNCTION("""COMPUTED_VALUE"""),105238.0) -> 105238 | S16: =IFERROR(__xludf.DUMMYFUNCTION("""COMPUTED_VALUE"""),3371.0) -> 3371 | T16: =IFERROR(__xludf.DUMMYFUNCTION("""COMPUTED_VALUE"""),217380.0) -> 217380 | V16: =IFERROR(__xludf.DUMMYFUNCTION("""COMPUTED_VALUE"""),56500.0) -> 56500 | W16: =IFERROR(__xludf.DUMMYFUNCTION("""COMPUTED_VALUE"""),2562.0) -> 2562 | X16: =IFERROR(__xludf.DUMMYFUNCTION("""COMPUTED_VALUE"""),79458.0) -> 79458 | Y16: =IFERROR(__xludf.DUMMYFUNCTION("""COMPUTED_VALUE"""),39200.0) -> 39200 | Z16: =IFERROR(__xludf.DUMMYFUNCTION("""COMPUTED_VALUE"""),175000.0) -> 175000 | AA16: =IFERROR(__xludf.DUMMYFUNCTION("""COMPUTED_VALUE"""),33725.0) -> 33725 | AB16: =IFERROR(__xludf.DUMMYFUNCTION("""COMPUTED_VALUE"""),372024.0) -> 372024 | AC16: 1789226
B17: =IFERROR(__xludf.DUMMYFUNCTION("""COMPUTED_VALUE"""),2025.0) -> 2025 | C17: =IFERROR(__xludf.DUMMYFUNCTION("""COMPUTED_VALUE"""),11130.0) -> 11130 | D17: =IFERROR(__xludf.DUMMYFUNCTION("""COMPUTED_VALUE"""),626594.0) -> 626594 | E17: =IFERROR(__xludf.DUMMYFUNCTION("""COMPUTED_VALUE"""),238282.0) -> 238282 | F17: =IFERROR(__xludf.DUMMYFUNCTION("""COMPUTED_VALUE"""),185196.0) -> 185196 | G17: =IFERROR(__xludf.DUMMYFUNCTION("""COMPUTED_VALUE"""),574927.0) -> 574927 | H17: 1636129 | J17: =IFERROR(__xludf.DUMMYFUNCTION("""COMPUTED_VALUE"""),2025.0) -> 2025 | K17: =IFERROR(__xludf.DUMMYFUNCTION("""COMPUTED_VALUE"""),1697.0) -> 1697 | L17: =IFERROR(__xludf.DUMMYFUNCTION("""COMPUTED_VALUE"""),1451.0) -> 1451 | M17: =IFERROR(__xludf.DUMMYFUNCTION("""COMPUTED_VALUE"""),279.0) -> 279 | N17: =IFERROR(__xludf.DUMMYFUNCTION("""COMPUTED_VALUE"""),7703.0) -> 7703 | O17: =IFERROR(__xludf.DUMMYFUNCTION("""COMPUTED_VALUE"""),200361.0) -> 200361 | P17: =IFERROR(__xludf.DUMMYFUNCTION("""COMPUTED_VALUE"""),896.0) -> 896 | Q17: =IFERROR(__xludf.DUMMYFUNCTION("""COMPUTED_VALUE"""),425337.0) -> 425337 | R17: =IFERROR(__xludf.DUMMYFUNCTION("""COMPUTED_VALUE"""),83675.0) -> 83675 | S17: =IFERROR(__xludf.DUMMYFUNCTION("""COMPUTED_VALUE"""),1070.0) -> 1070 | T17: =IFERROR(__xludf.DUMMYFUNCTION("""COMPUTED_VALUE"""),153537.0) -> 153537 | U17: =IFERROR(__xludf.DUMMYFUNCTION("""COMPUTED_VALUE"""),356.0) -> 356 | V17: =IFERROR(__xludf.DUMMYFUNCTION("""COMPUTED_VALUE"""),37071.0) -> 37071 | W17: =IFERROR(__xludf.DUMMYFUNCTION("""COMPUTED_VALUE"""),870.0) -> 870 | X17: =IFERROR(__xludf.DUMMYFUNCTION("""COMPUTED_VALUE"""),146899.0) -> 146899 | Y17: =IFERROR(__xludf.DUMMYFUNCTION("""COMPUTED_VALUE"""),18768.0) -> 18768 | Z17: =IFERROR(__xludf.DUMMYFUNCTION("""COMPUTED_VALUE"""),166810.0) -> 166810 | AA17: =IFERROR(__xludf.DUMMYFUNCTION("""COMPUTED_VALUE"""),26914.0) -> 26914 | AB17: =IFERROR(__xludf.DUMMYFUNCTION("""COMPUTED_VALUE"""),362435.0) -> 362435 | AC17: 1636129
B18: =IFERROR(__xludf.DUMMYFUNCTION("""COMPUTED_VALUE"""),"Total") -> Total | C18: =IFERROR(__xludf.DUMMYFUNCTION("""COMPUTED_VALUE"""),227884.0) -> 227884 | D18: =IFERROR(__xludf.DUMMYFUNCTION("""COMPUTED_VALUE"""),2891283.0) -> 2891283 | E18: =IFERROR(__xludf.DUMMYFUNCTION("""COMPUTED_VALUE"""),1646943.0) -> 1646943 | F18: =IFERROR(__xludf.DUMMYFUNCTION("""COMPUTED_VALUE"""),657995.0) -> 657995 | G18: =IFERROR(__xludf.DUMMYFUNCTION("""COMPUTED_VALUE"""),3459619.0) -> 3459619 | H18: 8883724 | J18: =IFERROR(__xludf.DUMMYFUNCTION("""COMPUTED_VALUE"""),"Total") -> Total | K18: =IFERROR(__xludf.DUMMYFUNCTION("""COMPUTED_VALUE"""),3237.0) -> 3237 | L18: =IFERROR(__xludf.DUMMYFUNCTION("""COMPUTED_VALUE"""),104339.0) -> 104339 | M18: =IFERROR(__xludf.DUMMYFUNCTION("""COMPUTED_VALUE"""),23207.0) -> 23207 | N18: =IFERROR(__xludf.DUMMYFUNCTION("""COMPUTED_VALUE"""),97101.0) -> 97101 | O18: =IFERROR(__xludf.DUMMYFUNCTION("""COMPUTED_VALUE"""),968981.0) -> 968981 | P18: =IFERROR(__xludf.DUMMYFUNCTION("""COMPUTED_VALUE"""),75095.0) -> 75095 | Q18: =IFERROR(__xludf.DUMMYFUNCTION("""COMPUTED_VALUE"""),1847207.0) -> 1847207 | R18: =IFERROR(__xludf.DUMMYFUNCTION("""COMPUTED_VALUE"""),709725.0) -> 709725 | S18: =IFERROR(__xludf.DUMMYFUNCTION("""COMPUTED_VALUE"""),147042.0) -> 147042 | T18: =IFERROR(__xludf.DUMMYFUNCTION("""COMPUTED_VALUE"""),790176.0) -> 790176 | U18: =IFERROR(__xludf.DUMMYFUNCTION("""COMPUTED_VALUE"""),356.0) -> 356 | V18: =IFERROR(__xludf.DUMMYFUNCTION("""COMPUTED_VALUE"""),249445.0) -> 249445 | W18: =IFERROR(__xludf.DUMMYFUNCTION("""COMPUTED_VALUE"""),33568.0) -> 33568 | X18: =IFERROR(__xludf.DUMMYFUNCTION("""COMPUTED_VALUE"""),374626.0) -> 374626 | Y18: =IFERROR(__xludf.DUMMYFUNCTION("""COMPUTED_VALUE"""),58092.0) -> 58092 | Z18: =IFERROR(__xludf.DUMMYFUNCTION("""COMPUTED_VALUE"""),1299275.0) -> 1299275 | AA18: =IFERROR(__xludf.DUMMYFUNCTION("""COMPUTED_VALUE"""),464394.0) -> 464394 | AB18: =IFERROR(__xludf.DUMMYFUNCTION("""COMPUTED_VALUE"""),1637858.0) -> 1637858 | AC18: 8883724
K22: =IFERROR(__xludf.DUMMYFUNCTION("transpose(split(K24,"",""))"),"Canada") -> Canada | L22: =IFERROR(__xludf.DUMMYFUNCTION("transpose(split(L24,"",""))"),"Canada") -> Canada | M22: =IFERROR(__xludf.DUMMYFUNCTION("transpose(split(M24,"",""))"),"Canada") -> Canada | N22: =IFERROR(__xludf.DUMMYFUNCTION("transpose(split(N24,"",""))"),"Canada") -> Canada | O22: =IFERROR(__xludf.DUMMYFUNCTION("transpose(split(O24,"",""))"),"China") -> China | P22: =IFERROR(__xludf.DUMMYFUNCTION("transpose(split(P24,"",""))"),"China") -> China | Q22: =IFERROR(__xludf.DUMMYFUNCTION("transpose(split(Q24,"",""))"),"China") -> China | R22: =IFERROR(__xludf.DUMMYFUNCTION("transpose(split(R24,"",""))"),"Europe") -> Europe | S22: =IFERROR(__xludf.DUMMYFUNCTION("transpose(split(S24,"",""))"),"Europe") -> Europe | T22: =IFERROR(__xludf.DUMMYFUNCTION("transpose(split(T24,"",""))"),"Europe") -> Europe | U22: =IFERROR(__xludf.DUMMYFUNCTION("transpose(split(U24,"",""))"),"ROW") -> ROW | V22: =IFERROR(__xludf.DUMMYFUNCTION("transpose(split(V24,"",""))"),"ROW") -> ROW | W22: =IFERROR(__xludf.DUMMYFUNCTION("transpose(split(W24,"",""))"),"ROW") -> ROW | X22: =IFERROR(__xludf.DUMMYFUNCTION("transpose(split(X24,"",""))"),"ROW") -> ROW | Y22: =IFERROR(__xludf.DUMMYFUNCTION("transpose(split(Y24,"",""))"),"USA") -> USA | Z22: =IFERROR(__xludf.DUMMYFUNCTION("transpose(split(Z24,"",""))"),"USA") -> USA | AA22: =IFERROR(__xludf.DUMMYFUNCTION("transpose(split(AA24,"",""))"),"USA") -> USA | AB22: =IFERROR(__xludf.DUMMYFUNCTION("transpose(split(AB24,"",""))"),"USA") -> USA | AC22: Total
B23: Deliveries | C23: =IFERROR(__xludf.DUMMYFUNCTION("transpose(split(C24,"",""))"),"Canada") -> Canada | D23: =IFERROR(__xludf.DUMMYFUNCTION("transpose(split(D24,"",""))"),"China") -> China | E23: =IFERROR(__xludf.DUMMYFUNCTION("transpose(split(E24,"",""))"),"Europe") -> Europe | F23: =IFERROR(__xludf.DUMMYFUNCTION("transpose(split(F24,"",""))"),"ROW") -> ROW | G23: =IFERROR(__xludf.DUMMYFUNCTION("transpose(split(G24,"",""))"),"USA") -> USA | H23: Total | J23: Deliveries | K23: =IFERROR(__xludf.DUMMYFUNCTION("""COMPUTED_VALUE"""),"Cybertruck") -> Cybertruck | L23: =IFERROR(__xludf.DUMMYFUNCTION("""COMPUTED_VALUE"""),"Model 3") -> Model 3 | M23: =IFERROR(__xludf.DUMMYFUNCTION("""COMPUTED_VALUE"""),"Model S/X") -> Model S/X | N23: =IFERROR(__xludf.DUMMYFUNCTION("""COMPUTED_VALUE"""),"Model Y") -> Model Y | O23: =IFERROR(__xludf.DUMMYFUNCTION("""COMPUTED_VALUE"""),"Model 3") -> Model 3 | P23: =IFERROR(__xludf.DUMMYFUNCTION("""COMPUTED_VALUE"""),"Model S/X") -> Model S/X | Q23: =IFERROR(__xludf.DUMMYFUNCTION("""COMPUTED_VALUE"""),"Model Y") -> Model Y | R23: =IFERROR(__xludf.DUMMYFUNCTION("""COMPUTED_VALUE"""),"Model 3") -> Model 3 | S23: =IFERROR(__xludf.DUMMYFUNCTION("""COMPUTED_VALUE"""),"Model S/X") -> Model S/X | T23: =IFERROR(__xludf.DUMMYFUNCTION("""COMPUTED_VALUE"""),"Model Y") -> Model Y | U23: =IFERROR(__xludf.DUMMYFUNCTION("""COMPUTED_VALUE"""),"Cybertruck") -> Cybertruck | V23: =IFERROR(__xludf.DUMMYFUNCTION("""COMPUTED_VALUE"""),"Model 3") -> Model 3 | W23: =IFERROR(__xludf.DUMMYFUNCTION("""COMPUTED_VALUE"""),"Model S/X") -> Model S/X | X23: =IFERROR(__xludf.DUMMYFUNCTION("""COMPUTED_VALUE"""),"Model Y") -> Model Y | Y23: =IFERROR(__xludf.DUMMYFUNCTION("""COMPUTED_VALUE"""),"Cybertruck") -> Cybertruck | Z23: =IFERROR(__xludf.DUMMYFUNCTION("""COMPUTED_VALUE"""),"Model 3") -> Model 3 | AA23: =IFERROR(__xludf.DUMMYFUNCTION("""COMPUTED_VALUE"""),"Model S/X") -> Model S/X | AB23: =IFERROR(__xludf.DUMMYFUNCTION("""COMPUTED_VALUE"""),"Model Y") -> Model Y | AC23: All models
B24: =IFERROR(__xludf.DUMMYFUNCTION("{query({Delivery_Data!$A:$I},""select Col3,sum(Col8) where Col3 is not null and Col8 is not null group by Col3 pivot Col6"",1);index(query({Delivery_Data!$A:$I},""select 'Total',sum(Col8) where Col3 is not null and Col8 is not null pivot Col6"",1),2,0)}"),"Quarter") -> Quarter | C24: =IFERROR(__xludf.DUMMYFUNCTION("""COMPUTED_VALUE"""),"Canada") -> Canada | D24: =IFERROR(__xludf.DUMMYFUNCTION("""COMPUTED_VALUE"""),"China") -> China | E24: =IFERROR(__xludf.DUMMYFUNCTION("""COMPUTED_VALUE"""),"Europe") -> Europe | F24: =IFERROR(__xludf.DUMMYFUNCTION("""COMPUTED_VALUE"""),"ROW") -> ROW | G24: =IFERROR(__xludf.DUMMYFUNCTION("""COMPUTED_VALUE"""),"USA") -> USA | H24: {={"Total";if($B25:$B79="",,mmult(n($C$25:$G$79),transpose(sign(column($C$25:$G$79)))))}} -> Total | J24: =IFERROR(__xludf.DUMMYFUNCTION("{query({Delivery_Data!$A:$I},""select Col3,sum(Col8) where Col3 is not null and Col8 is not null group by Col3 pivot Col6,Col4"",1);index(query({Delivery_Data!$A:$I},""select 'Total',sum(Col8) where Col3 is not null and Col8 is not null pivot Col6,Col4"","&"1),2,0)}"),"Quarter") -> Quarter | K24: =IFERROR(__xludf.DUMMYFUNCTION("""COMPUTED_VALUE"""),"Canada,Cybertruck") -> Canada,Cybertruck | L24: =IFERROR(__xludf.DUMMYFUNCTION("""COMPUTED_VALUE"""),"Canada,Model 3") -> Canada,Model 3 | M24: =IFERROR(__xludf.DUMMYFUNCTION("""COMPUTED_VALUE"""),"Canada,Model S/X") -> Canada,Model S/X | N24: =IFERROR(__xludf.DUMMYFUNCTION("""COMPUTED_VALUE"""),"Canada,Model Y") -> Canada,Model Y | O24: =IFERROR(__xludf.DUMMYFUNCTION("""COMPUTED_VALUE"""),"China,Model 3") -> China,Model 3 | P24: =IFERROR(__xludf.DUMMYFUNCTION("""COMPUTED_VALUE"""),"China,Model S/X") -> China,Model S/X | Q24: =IFERROR(__xludf.DUMMYFUNCTION("""COMPUTED_VALUE"""),"China,Model Y") -> China,Model Y | R24: =IFERROR(__xludf.DUMMYFUNCTION("""COMPUTED_VALUE"""),"Europe,Model 3") -> Europe,Model 3 | S24: =IFERROR(__xludf.DUMMYFUNCTION("""COMPUTED_VALUE"""),"Europe,Model S/X") -> Europe,Model S/X | T24: =IFERROR(__xludf.DUMMYFUNCTION("""COMPUTED_VALUE"""),"Europe,Model Y") -> Europe,Model Y | U24: =IFERROR(__xludf.DUMMYFUNCTION("""COMPUTED_VALUE"""),"ROW,Cybertruck") -> ROW,Cybertruck | V24: =IFERROR(__xludf.DUMMYFUNCTION("""COMPUTED_VALUE"""),"ROW,Model 3") -> ROW,Model 3 | W24: =IFERROR(__xludf.DUMMYFUNCTION("""COMPUTED_VALUE"""),"ROW,Model S/X") -> ROW,Model S/X | X24: =IFERROR(__xludf.DUMMYFUNCTION("""COMPUTED_VALUE"""),"ROW,Model Y") -> ROW,Model Y | Y24: =IFERROR(__xludf.DUMMYFUNCTION("""COMPUTED_VALUE"""),"USA,Cybertruck") -> USA,Cybertruck | Z24: =IFERROR(__xludf.DUMMYFUNCTION("""COMPUTED_VALUE"""),"USA,Model 3") -> USA,Model 3 | AA24: =IFERROR(__xludf.DUMMYFUNCTION("""COMPUTED_VALUE"""),"USA,Model S/X") -> USA,Model S/X | AB24: =IFERROR(__xludf.DUMMYFUNCTION("""COMPUTED_VALUE"""),"USA,Model Y") -> USA,Model Y | AC24: {={"Total";if($J25:$J79="",,mmult(n($K$25:$AB$79),transpose(sign(column($K$25:$AB$79)))))}} -> Total
B25: =IFERROR(__xludf.DUMMYFUNCTION("""COMPUTED_VALUE"""),"2012 Q3") -> 2012 Q3 | G25: =IFERROR(__xludf.DUMMYFUNCTION("""COMPUTED_VALUE"""),253.0) -> 253 | H25: 253 | J25: =IFERROR(__xludf.DUMMYFUNCTION("""COMPUTED_VALUE"""),"2012 Q3") -> 2012 Q3 | AA25: =IFERROR(__xludf.DUMMYFUNCTION("""COMPUTED_VALUE"""),253.0) -> 253 | AC25: 253
B26: =IFERROR(__xludf.DUMMYFUNCTION("""COMPUTED_VALUE"""),"2012 Q4") -> 2012 Q4 | C26: =IFERROR(__xludf.DUMMYFUNCTION("""COMPUTED_VALUE"""),95.0) -> 95 | G26: =IFERROR(__xludf.DUMMYFUNCTION("""COMPUTED_VALUE"""),2302.0) -> 2302 | H26: 2397 | J26: =IFERROR(__xludf.DUMMYFUNCTION("""COMPUTED_VALUE"""),"2012 Q4") -> 2012 Q4 | M26: =IFERROR(__xludf.DUMMYFUNCTION("""COMPUTED_VALUE"""),95.0) -> 95 | AA26: =IFERROR(__xludf.DUMMYFUNCTION("""COMPUTED_VALUE"""),2302.0) -> 2302 | AC26: 2397
B27: =IFERROR(__xludf.DUMMYFUNCTION("""COMPUTED_VALUE"""),"2013 Q1") -> 2013 Q1 | C27: =IFERROR(__xludf.DUMMYFUNCTION("""COMPUTED_VALUE"""),158.0) -> 158 | G27: =IFERROR(__xludf.DUMMYFUNCTION("""COMPUTED_VALUE"""),4753.0) -> 4753 | H27: 4911 | J27: =IFERROR(__xludf.DUMMYFUNCTION("""COMPUTED_VALUE"""),"2013 Q1") -> 2013 Q1 | M27: =IFERROR(__xludf.DUMMYFUNCTION("""COMPUTED_VALUE"""),158.0) -> 158 | AA27: =IFERROR(__xludf.DUMMYFUNCTION("""COMPUTED_VALUE"""),4753.0) -> 4753 | AC27: 4911
B28: =IFERROR(__xludf.DUMMYFUNCTION("""COMPUTED_VALUE"""),"2013 Q2") -> 2013 Q2 | C28: =IFERROR(__xludf.DUMMYFUNCTION("""COMPUTED_VALUE"""),184.0) -> 184 | G28: =IFERROR(__xludf.DUMMYFUNCTION("""COMPUTED_VALUE"""),4978.0) -> 4978 | H28: 5162 | J28: =IFERROR(__xludf.DUMMYFUNCTION("""COMPUTED_VALUE"""),"2013 Q2") -> 2013 Q2 | M28: =IFERROR(__xludf.DUMMYFUNCTION("""COMPUTED_VALUE"""),184.0) -> 184 | AA28: =IFERROR(__xludf.DUMMYFUNCTION("""COMPUTED_VALUE"""),4978.0) -> 4978 | AC28: 5162
B29: =IFERROR(__xludf.DUMMYFUNCTION("""COMPUTED_VALUE"""),"2013 Q3") -> 2013 Q3 | C29: =IFERROR(__xludf.DUMMYFUNCTION("""COMPUTED_VALUE"""),162.0) -> 162 | E29: =IFERROR(__xludf.DUMMYFUNCTION("""COMPUTED_VALUE"""),1224.0) -> 1224 | G29: =IFERROR(__xludf.DUMMYFUNCTION("""COMPUTED_VALUE"""),4126.0) -> 4126 | H29: 5512 | J29: =IFERROR(__xludf.DUMMYFUNCTION("""COMPUTED_VALUE"""),"2013 Q3") -> 2013 Q3 | M29: =IFERROR(__xludf.DUMMYFUNCTION("""COMPUTED_VALUE"""),162.0) -> 162 | S29: =IFERROR(__xludf.DUMMYFUNCTION("""COMPUTED_VALUE"""),1224.0) -> 1224 | AA29: =IFERROR(__xludf.DUMMYFUNCTION("""COMPUTED_VALUE"""),4126.0) -> 4126 | AC29: 5512
B30: =IFERROR(__xludf.DUMMYFUNCTION("""COMPUTED_VALUE"""),"2013 Q4") -> 2013 Q4 | C30: =IFERROR(__xludf.DUMMYFUNCTION("""COMPUTED_VALUE"""),134.0) -> 134 | E30: =IFERROR(__xludf.DUMMYFUNCTION("""COMPUTED_VALUE"""),2669.0) -> 2669 | G30: =IFERROR(__xludf.DUMMYFUNCTION("""COMPUTED_VALUE"""),4089.0) -> 4089 | H30: 6892 | J30: =IFERROR(__xludf.DUMMYFUNCTION("""COMPUTED_VALUE"""),"2013 Q4") -> 2013 Q4 | M30: =IFERROR(__xludf.DUMMYFUNCTION("""COMPUTED_VALUE"""),134.0) -> 134 | S30: =IFERROR(__xludf.DUMMYFUNCTION("""COMPUTED_VALUE"""),2669.0) -> 2669 | AA30: =IFERROR(__xludf.DUMMYFUNCTION("""COMPUTED_VALUE"""),4089.0) -> 4089 | AC30: 6892
B31: =IFERROR(__xludf.DUMMYFUNCTION("""COMPUTED_VALUE"""),"2014 Q1") -> 2014 Q1 | C31: =IFERROR(__xludf.DUMMYFUNCTION("""COMPUTED_VALUE"""),158.0) -> 158 | D31: =IFERROR(__xludf.DUMMYFUNCTION("""COMPUTED_VALUE"""),3.0) -> 3 | E31: =IFERROR(__xludf.DUMMYFUNCTION("""COMPUTED_VALUE"""),3073.0) -> 3073 | G31: =IFERROR(__xludf.DUMMYFUNCTION("""COMPUTED_VALUE"""),3223.0) -> 3223 | H31: 6457 | J31: =IFERROR(__xludf.DUMMYFUNCTION("""COMPUTED_VALUE"""),"2014 Q1") -> 2014 Q1 | M31: =IFERROR(__xludf.DUMMYFUNCTION("""COMPUTED_VALUE"""),158.0) -> 158 | P31: =IFERROR(__xludf.DUMMYFUNCTION("""COMPUTED_VALUE"""),3.0) -> 3 | S31: =IFERROR(__xludf.DUMMYFUNCTION("""COMPUTED_VALUE"""),3073.0) -> 3073 | AA31: =IFERROR(__xludf.DUMMYFUNCTION("""COMPUTED_VALUE"""),3223.0) -> 3223 | AC31: 6457
B32: =IFERROR(__xludf.DUMMYFUNCTION("""COMPUTED_VALUE"""),"2014 Q2") -> 2014 Q2 | C32: =IFERROR(__xludf.DUMMYFUNCTION("""COMPUTED_VALUE"""),186.0) -> 186 | D32: =IFERROR(__xludf.DUMMYFUNCTION("""COMPUTED_VALUE"""),1543.0) -> 1543 | E32: =IFERROR(__xludf.DUMMYFUNCTION("""COMPUTED_VALUE"""),2519.0) -> 2519 | G32: =IFERROR(__xludf.DUMMYFUNCTION("""COMPUTED_VALUE"""),3331.0) -> 3331 | H32: 7579 | J32: =IFERROR(__xludf.DUMMYFUNCTION("""COMPUTED_VALUE"""),"2014 Q2") -> 2014 Q2 | M32: =IFERROR(__xludf.DUMMYFUNCTION("""COMPUTED_VALUE"""),186.0) -> 186 | P32: =IFERROR(__xludf.DUMMYFUNCTION("""COMPUTED_VALUE"""),1543.0) -> 1543 | S32: =IFERROR(__xludf.DUMMYFUNCTION("""COMPUTED_VALUE"""),2519.0) -> 2519 | AA32: =IFERROR(__xludf.DUMMYFUNCTION("""COMPUTED_VALUE"""),3331.0) -> 3331 | AC32: 7579
B33: =IFERROR(__xludf.DUMMYFUNCTION("""COMPUTED_VALUE"""),"2014 Q3") -> 2014 Q3 | C33: =IFERROR(__xludf.DUMMYFUNCTION("""COMPUTED_VALUE"""),230.0) -> 230 | D33: =IFERROR(__xludf.DUMMYFUNCTION("""COMPUTED_VALUE"""),1026.0) -> 1026 | E33: =IFERROR(__xludf.DUMMYFUNCTION("""COMPUTED_VALUE"""),1653.0) -> 1653 | F33: =IFERROR(__xludf.DUMMYFUNCTION("""COMPUTED_VALUE"""),162.0) -> 162 | G33: =IFERROR(__xludf.DUMMYFUNCTION("""COMPUTED_VALUE"""),4714.0) -> 4714 | H33: 7785 | J33: =IFERROR(__xludf.DUMMYFUNCTION("""COMPUTED_VALUE"""),"2014 Q3") -> 2014 Q3 | M33: =IFERROR(__xludf.DUMMYFUNCTION("""COMPUTED_VALUE"""),230.0) -> 230 | P33: =IFERROR(__xludf.DUMMYFUNCTION("""COMPUTED_VALUE"""),1026.0) -> 1026 | S33: =IFERROR(__xludf.DUMMYFUNCTION("""COMPUTED_VALUE"""),1653.0) -> 1653 | W33: =IFERROR(__xludf.DUMMYFUNCTION("""COMPUTED_VALUE"""),162.0) -> 162 | AA33: =IFERROR(__xludf.DUMMYFUNCTION("""COMPUTED_VALUE"""),4714.0) -> 4714 | AC33: 7785
B34: =IFERROR(__xludf.DUMMYFUNCTION("""COMPUTED_VALUE"""),"2014 Q4") -> 2014 Q4 | C34: =IFERROR(__xludf.DUMMYFUNCTION("""COMPUTED_VALUE"""),210.0) -> 210 | D34: =IFERROR(__xludf.DUMMYFUNCTION("""COMPUTED_VALUE"""),1550.0) -> 1550 | E34: =IFERROR(__xludf.DUMMYFUNCTION("""COMPUTED_VALUE"""),2276.0) -> 2276 | F34: =IFERROR(__xludf.DUMMYFUNCTION("""COMPUTED_VALUE"""),377.0) -> 377 | G34: =IFERROR(__xludf.DUMMYFUNCTION("""COMPUTED_VALUE"""),5421.0) -> 5421 | H34: 9834 | J34: =IFERROR(__xludf.DUMMYFUNCTION("""COMPUTED_VALUE"""),"2014 Q4") -> 2014 Q4 | M34: =IFERROR(__xludf.DUMMYFUNCTION("""COMPUTED_VALUE"""),210.0) -> 210 | P34: =IFERROR(__xludf.DUMMYFUNCTION("""COMPUTED_VALUE"""),1550.0) -> 1550 | S34: =IFERROR(__xludf.DUMMYFUNCTION("""COMPUTED_VALUE"""),2276.0) -> 2276 | W34: =IFERROR(__xludf.DUMMYFUNCTION("""COMPUTED_VALUE"""),377.0) -> 377 | AA34: =IFERROR(__xludf.DUMMYFUNCTION("""COMPUTED_VALUE"""),5421.0) -> 5421 | AC34: 9834
B35: =IFERROR(__xludf.DUMMYFUNCTION("""COMPUTED_VALUE"""),"2015 Q1") -> 2015 Q1 | C35: =IFERROR(__xludf.DUMMYFUNCTION("""COMPUTED_VALUE"""),290.0) -> 290 | D35: =IFERROR(__xludf.DUMMYFUNCTION("""COMPUTED_VALUE"""),1055.0) -> 1055 | E35: =IFERROR(__xludf.DUMMYFUNCTION("""COMPUTED_VALUE"""),3465.0) -> 3465 | F35: =IFERROR(__xludf.DUMMYFUNCTION("""COMPUTED_VALUE"""),610.0) -> 610 | G35: =IFERROR(__xludf.DUMMYFUNCTION("""COMPUTED_VALUE"""),4625.0) -> 4625 | H35: 10045 | J35: =IFERROR(__xludf.DUMMYFUNCTION("""COMPUTED_VALUE"""),"2015 Q1") -> 2015 Q1 | M35: =IFERROR(__xludf.DUMMYFUNCTION("""COMPUTED_VALUE"""),290.0) -> 290 | P35: =IFERROR(__xludf.DUMMYFUNCTION("""COMPUTED_VALUE"""),1055.0) -> 1055 | S35: =IFERROR(__xludf.DUMMYFUNCTION("""COMPUTED_VALUE"""),3465.0) -> 3465 | W35: =IFERROR(__xludf.DUMMYFUNCTION("""COMPUTED_VALUE"""),610.0) -> 610 | AA35: =IFERROR(__xludf.DUMMYFUNCTION("""COMPUTED_VALUE"""),4625.0) -> 4625 | AC35: 10045
B36: =IFERROR(__xludf.DUMMYFUNCTION("""COMPUTED_VALUE"""),"2015 Q2") -> 2015 Q2 | C36: =IFERROR(__xludf.DUMMYFUNCTION("""COMPUTED_VALUE"""),382.0) -> 382 | D36: =IFERROR(__xludf.DUMMYFUNCTION("""COMPUTED_VALUE"""),737.0) -> 737 | E36: =IFERROR(__xludf.DUMMYFUNCTION("""COMPUTED_VALUE"""),3891.0) -> 3891 | F36: =IFERROR(__xludf.DUMMYFUNCTION("""COMPUTED_VALUE"""),499.0) -> 499 | G36: =IFERROR(__xludf.DUMMYFUNCTION("""COMPUTED_VALUE"""),6023.0) -> 6023 | H36: 11532 | J36: =IFERROR(__xludf.DUMMYFUNCTION("""COMPUTED_VALUE"""),"2015 Q2") -> 2015 Q2 | M36: =IFERROR(__xludf.DUMMYFUNCTION("""COMPUTED_VALUE"""),382.0) -> 382 | P36: =IFERROR(__xludf.DUMMYFUNCTION("""COMPUTED_VALUE"""),737.0) -> 737 | S36: =IFERROR(__xludf.DUMMYFUNCTION("""COMPUTED_VALUE"""),3891.0) -> 3891 | W36: =IFERROR(__xludf.DUMMYFUNCTION("""COMPUTED_VALUE"""),499.0) -> 499 | AA36: =IFERROR(__xludf.DUMMYFUNCTION("""COMPUTED_VALUE"""),6023.0) -> 6023 | AC36: 11532
B37: =IFERROR(__xludf.DUMMYFUNCTION("""COMPUTED_VALUE"""),"2015 Q3") -> 2015 Q3 | C37: =IFERROR(__xludf.DUMMYFUNCTION("""COMPUTED_VALUE"""),386.0) -> 386 | D37: =IFERROR(__xludf.DUMMYFUNCTION("""COMPUTED_VALUE"""),842.0) -> 842 | E37: =IFERROR(__xludf.DUMMYFUNCTION("""COMPUTED_VALUE"""),3520.0) -> 3520 | F37: =IFERROR(__xludf.DUMMYFUNCTION("""COMPUTED_VALUE"""),793.0) -> 793 | G37: =IFERROR(__xludf.DUMMYFUNCTION("""COMPUTED_VALUE"""),6062.0) -> 6062 | H37: 11603 | J37: =IFERROR(__xludf.DUMMYFUNCTION("""COMPUTED_VALUE"""),"2015 Q3") -> 2015 Q3 | M37: =IFERROR(__xludf.DUMMYFUNCTION("""COMPUTED_VALUE"""),386.0) -> 386 | P37: =IFERROR(__xludf.DUMMYFUNCTION("""COMPUTED_VALUE"""),842.0) -> 842 | S37: =IFERROR(__xludf.DUMMYFUNCTION("""COMPUTED_VALUE"""),3520.0) -> 3520 | W37: =IFERROR(__xludf.DUMMYFUNCTION("""COMPUTED_VALUE"""),793.0) -> 793 | AA37: =IFERROR(__xludf.DUMMYFUNCTION("""COMPUTED_VALUE"""),6062.0) -> 6062 | AC37: 11603
B38: =IFERROR(__xludf.DUMMYFUNCTION("""COMPUTED_VALUE"""),"2015 Q4") -> 2015 Q4 | C38: =IFERROR(__xludf.DUMMYFUNCTION("""COMPUTED_VALUE"""),542.0) -> 542 | D38: =IFERROR(__xludf.DUMMYFUNCTION("""COMPUTED_VALUE"""),1058.0) -> 1058 | E38: =IFERROR(__xludf.DUMMYFUNCTION("""COMPUTED_VALUE"""),5825.0) -> 5825 | F38: =IFERROR(__xludf.DUMMYFUNCTION("""COMPUTED_VALUE"""),1561.0) -> 1561 | G38: =IFERROR(__xludf.DUMMYFUNCTION("""COMPUTED_VALUE"""),8492.0) -> 8492 | H38: 17478 | J38: =IFERROR(__xludf.DUMMYFUNCTION("""COMPUTED_VALUE"""),"2015 Q4") -> 2015 Q4 | M38: =IFERROR(__xludf.DUMMYFUNCTION("""COMPUTED_VALUE"""),542.0) -> 542 | P38: =IFERROR(__xludf.DUMMYFUNCTION("""COMPUTED_VALUE"""),1058.0) -> 1058 | S38: =IFERROR(__xludf.DUMMYFUNCTION("""COMPUTED_VALUE"""),5825.0) -> 5825 | W38: =IFERROR(__xludf.DUMMYFUNCTION("""COMPUTED_VALUE"""),1561.0) -> 1561 | AA38: =IFERROR(__xludf.DUMMYFUNCTION("""COMPUTED_VALUE"""),8492.0) -> 8492 | AC38: 17478
B39: =IFERROR(__xludf.DUMMYFUNCTION("""COMPUTED_VALUE"""),"2016 Q1") -> 2016 Q1 | C39: =IFERROR(__xludf.DUMMYFUNCTION("""COMPUTED_VALUE"""),398.0) -> 398 | D39: =IFERROR(__xludf.DUMMYFUNCTION("""COMPUTED_VALUE"""),1361.0) -> 1361 | E39: =IFERROR(__xludf.DUMMYFUNCTION("""COMPUTED_VALUE"""),3849.0) -> 3849 | F39: =IFERROR(__xludf.DUMMYFUNCTION("""COMPUTED_VALUE"""),1150.0) -> 1150 | G39: =IFERROR(__xludf.DUMMYFUNCTION("""COMPUTED_VALUE"""),8052.0) -> 8052 | H39: 14810 | J39: =IFERROR(__xludf.DUMMYFUNCTION("""COMPUTED_VALUE"""),"2016 Q1") -> 2016 Q1 | M39: =IFERROR(__xludf.DUMMYFUNCTION("""COMPUTED_VALUE"""),398.0) -> 398 | P39: =IFERROR(__xludf.DUMMYFUNCTION("""COMPUTED_VALUE"""),1361.0) -> 1361 | S39: =IFERROR(__xludf.DUMMYFUNCTION("""COMPUTED_VALUE"""),3849.0) -> 3849 | W39: =IFERROR(__xludf.DUMMYFUNCTION("""COMPUTED_VALUE"""),1150.0) -> 1150 | AA39: =IFERROR(__xludf.DUMMYFUNCTION("""COMPUTED_VALUE"""),8052.0) -> 8052 | AC39: 14810
B40: =IFERROR(__xludf.DUMMYFUNCTION("""COMPUTED_VALUE"""),"2016 Q2") -> 2016 Q2 | C40: =IFERROR(__xludf.DUMMYFUNCTION("""COMPUTED_VALUE"""),465.0) -> 465 | D40: =IFERROR(__xludf.DUMMYFUNCTION("""COMPUTED_VALUE"""),782.0) -> 782 | E40: =IFERROR(__xludf.DUMMYFUNCTION("""COMPUTED_VALUE"""),2980.0) -> 2980 | F40: =IFERROR(__xludf.DUMMYFUNCTION("""COMPUTED_VALUE"""),564.0) -> 564 | G40: =IFERROR(__xludf.DUMMYFUNCTION("""COMPUTED_VALUE"""),9611.0) -> 9611 | H40: 14402 | J40: =IFERROR(__xludf.DUMMYFUNCTION("""COMPUTED_VALUE"""),"2016 Q2") -> 2016 Q2 | M40: =IFERROR(__xludf.DUMMYFUNCTION("""COMPUTED_VALUE"""),465.0) -> 465 | P40: =IFERROR(__xludf.DUMMYFUNCTION("""COMPUTED_VALUE"""),782.0) -> 782 | S40: =IFERROR(__xludf.DUMMYFUNCTION("""COMPUTED_VALUE"""),2980.0) -> 2980 | W40: =IFERROR(__xludf.DUMMYFUNCTION("""COMPUTED_VALUE"""),564.0) -> 564 | AA40: =IFERROR(__xludf.DUMMYFUNCTION("""COMPUTED_VALUE"""),9611.0) -> 9611 | AC40: 14402
B41: =IFERROR(__xludf.DUMMYFUNCTION("""COMPUTED_VALUE"""),"2016 Q3") -> 2016 Q3 | C41: =IFERROR(__xludf.DUMMYFUNCTION("""COMPUTED_VALUE"""),743.0) -> 743 | D41: =IFERROR(__xludf.DUMMYFUNCTION("""COMPUTED_VALUE"""),3324.0) -> 3324 | E41: =IFERROR(__xludf.DUMMYFUNCTION("""COMPUTED_VALUE"""),5001.0) -> 5001 | F41: =IFERROR(__xludf.DUMMYFUNCTION("""COMPUTED_VALUE"""),1265.0) -> 1265 | G41: =IFERROR(__xludf.DUMMYFUNCTION("""COMPUTED_VALUE"""),14488.0) -> 14488 | H41: 24821 | J41: =IFERROR(__xludf.DUMMYFUNCTION("""COMPUTED_VALUE"""),"2016 Q3") -> 2016 Q3 | M41: =IFERROR(__xludf.DUMMYFUNCTION("""COMPUTED_VALUE"""),743.0) -> 743 | P41: =IFERROR(__xludf.DUMMYFUNCTION("""COMPUTED_VALUE"""),3324.0) -> 3324 | S41: =IFERROR(__xludf.DUMMYFUNCTION("""COMPUTED_VALUE"""),5001.0) -> 5001 | W41: =IFERROR(__xludf.DUMMYFUNCTION("""COMPUTED_VALUE"""),1265.0) -> 1265 | AA41: =IFERROR(__xludf.DUMMYFUNCTION("""COMPUTED_VALUE"""),14488.0) -> 14488 | AC41: 24821
B42: =IFERROR(__xludf.DUMMYFUNCTION("""COMPUTED_VALUE"""),"2016 Q4") -> 2016 Q4 | C42: =IFERROR(__xludf.DUMMYFUNCTION("""COMPUTED_VALUE"""),677.0) -> 677 | D42: =IFERROR(__xludf.DUMMYFUNCTION("""COMPUTED_VALUE"""),2910.0) -> 2910 | E42: =IFERROR(__xludf.DUMMYFUNCTION("""COMPUTED_VALUE"""),4400.0) -> 4400 | F42: =IFERROR(__xludf.DUMMYFUNCTION("""COMPUTED_VALUE"""),681.0) -> 681 | G42: =IFERROR(__xludf.DUMMYFUNCTION("""COMPUTED_VALUE"""),13584.0) -> 13584 | H42: 22252 | J42: =IFERROR(__xludf.DUMMYFUNCTION("""COMPUTED_VALUE"""),"2016 Q4") -> 2016 Q4 | M42: =IFERROR(__xludf.DUMMYFUNCTION("""COMPUTED_VALUE"""),677.0) -> 677 | P42: =IFERROR(__xludf.DUMMYFUNCTION("""COMPUTED_VALUE"""),2910.0) -> 2910 | S42: =IFERROR(__xludf.DUMMYFUNCTION("""COMPUTED_VALUE"""),4400.0) -> 4400 | W42: =IFERROR(__xludf.DUMMYFUNCTION("""COMPUTED_VALUE"""),681.0) -> 681 | AA42: =IFERROR(__xludf.DUMMYFUNCTION("""COMPUTED_VALUE"""),13584.0) -> 13584 | AC42: 22252
B43: =IFERROR(__xludf.DUMMYFUNCTION("""COMPUTED_VALUE"""),"2017 Q1") -> 2017 Q1 | C43: =IFERROR(__xludf.DUMMYFUNCTION("""COMPUTED_VALUE"""),558.0) -> 558 | D43: =IFERROR(__xludf.DUMMYFUNCTION("""COMPUTED_VALUE"""),2285.0) -> 2285 | E43: =IFERROR(__xludf.DUMMYFUNCTION("""COMPUTED_VALUE"""),6689.0) -> 6689 | F43: =IFERROR(__xludf.DUMMYFUNCTION("""COMPUTED_VALUE"""),4408.0) -> 4408 | G43: =IFERROR(__xludf.DUMMYFUNCTION("""COMPUTED_VALUE"""),11111.0) -> 11111 | H43: 25051 | J43: =IFERROR(__xludf.DUMMYFUNCTION("""COMPUTED_VALUE"""),"2017 Q1") -> 2017 Q1 | M43: =IFERROR(__xludf.DUMMYFUNCTION("""COMPUTED_VALUE"""),558.0) -> 558 | P43: =IFERROR(__xludf.DUMMYFUNCTION("""COMPUTED_VALUE"""),2285.0) -> 2285 | S43: =IFERROR(__xludf.DUMMYFUNCTION("""COMPUTED_VALUE"""),6689.0) -> 6689 | W43: =IFERROR(__xludf.DUMMYFUNCTION("""COMPUTED_VALUE"""),4408.0) -> 4408 | AA43: =IFERROR(__xludf.DUMMYFUNCTION("""COMPUTED_VALUE"""),11111.0) -> 11111 | AC43: 25051
...

Sheet Deliveries 2
I1: =IFERROR(__xludf.DUMMYFUNCTION("transpose(split(I3,"",""))"),"APAC") -> APAC | J1: =IFERROR(__xludf.DUMMYFUNCTION("transpose(split(J3,"",""))"),"APAC") -> APAC | K1: =IFERROR(__xludf.DUMMYFUNCTION("transpose(split(K3,"",""))"),"APAC") -> APAC | L1: =IFERROR(__xludf.DUMMYFUNCTION("transpose(split(L3,"",""))"),"APAC") -> APAC | M1: =IFERROR(__xludf.DUMMYFUNCTION("transpose(split(M3,"",""))"),"Europe") -> Europe | N1: =IFERROR(__xludf.DUMMYFUNCTION("transpose(split(N3,"",""))"),"Europe") -> Europe | O1: =IFERROR(__xludf.DUMMYFUNCTION("transpose(split(O3,"",""))"),"Europe") -> Europe | P1: =IFERROR(__xludf.DUMMYFUNCTION("transpose(split(P3,"",""))"),"North America") -> North America | Q1: =IFERROR(__xludf.DUMMYFUNCTION("transpose(split(Q3,"",""))"),"North America") -> North America | R1: =IFERROR(__xludf.DUMMYFUNCTION("transpose(split(R3,"",""))"),"North America") -> North America | S1: =IFERROR(__xludf.DUMMYFUNCTION("transpose(split(S3,"",""))"),"North America") -> North America | T1: Total
B2: Deliveries | C2: =C3 -> APAC | D2: =D3 -> Europe | E2: =E3 -> North America | F2: {={"All models";"";if($H4:$H18="",,mmult(n($I$4:$S$18),transpose(sign(column($I$4:$S$18)))))}} -> All models | H2: Deliveries | I2: =IFERROR(__xludf.DUMMYFUNCTION("""COMPUTED_VALUE"""),"Cybertruck") -> Cybertruck | J2: =IFERROR(__xludf.DUMMYFUNCTION("""COMPUTED_VALUE"""),"Model 3") -> Model 3 | K2: =IFERROR(__xludf.DUMMYFUNCTION("""COMPUTED_VALUE"""),"Model S/X") -> Model S/X | L2: =IFERROR(__xludf.DUMMYFUNCTION("""COMPUTED_VALUE"""),"Model Y") -> Model Y | M2: =IFERROR(__xludf.DUMMYFUNCTION("""COMPUTED_VALUE"""),"Model 3") -> Model 3 | N2: =IFERROR(__xludf.DUMMYFUNCTION("""COMPUTED_VALUE"""),"Model S/X") -> Model S/X | O2: =IFERROR(__xludf.DUMMYFUNCTION("""COMPUTED_VALUE"""),"Model Y") -> Model Y | P2: =IFERROR(__xludf.DUMMYFUNCTION("""COMPUTED_VALUE"""),"Cybertruck") -> Cybertruck | Q2: =IFERROR(__xludf.DUMMYFUNCTION("""COMPUTED_VALUE"""),"Model 3") -> Model 3 | R2: =IFERROR(__xludf.DUMMYFUNCTION("""COMPUTED_VALUE"""),"Model S/X") -> Model S/X | S2: =IFERROR(__xludf.DUMMYFUNCTION("""COMPUTED_VALUE"""),"Model Y") -> Model Y | T2: {={"All models";"";if($H4:$H18="",,mmult(n($I$4:$S$18),transpose(sign(column($I$4:$S$18)))))}} -> All models
B3: =IFERROR(__xludf.DUMMYFUNCTION("{query({Delivery_Data!$A:$I},""select Col1,sum(Col8) where Col1 is not null and Col8 is not null group by Col1 pivot Col7"",1);index(query({Delivery_Data!$A:$I},""select 'Total',sum(Col8) where Col1 is not null and Col8 is not null pivot Col7"",1),2,0)}"),"Year") -> Year | C3: =IFERROR(__xludf.DUMMYFUNCTION("""COMPUTED_VALUE"""),"APAC") -> APAC | D3: =IFERROR(__xludf.DUMMYFUNCTION("""COMPUTED_VALUE"""),"Europe") -> Europe | E3: =IFERROR(__xludf.DUMMYFUNCTION("""COMPUTED_VALUE"""),"North America") -> North America | H3: =IFERROR(__xludf.DUMMYFUNCTION("{query({Delivery_Data!$A:$I},""select Col1,sum(Col8) where Col1 is not null and Col8 is not null group by Col1 pivot Col7,Col4"",1);index(query({Delivery_Data!$A:$I},""select 'Total',sum(Col8) where Col1 is not null and Col8 is not null pivot Col7,Col4"","&"1),2,0)}"),"Year") -> Year | I3: =IFERROR(__xludf.DUMMYFUNCTION("""COMPUTED_VALUE"""),"APAC,Cybertruck") -> APAC,Cybertruck | J3: =IFERROR(__xludf.DUMMYFUNCTION("""COMPUTED_VALUE"""),"APAC,Model 3") -> APAC,Model 3 | K3: =IFERROR(__xludf.DUMMYFUNCTION("""COMPUTED_VALUE"""),"APAC,Model S/X") -> APAC,Model S/X | L3: =IFERROR(__xludf.DUMMYFUNCTION("""COMPUTED_VALUE"""),"APAC,Model Y") -> APAC,Model Y | M3: =IFERROR(__xludf.DUMMYFUNCTION("""COMPUTED_VALUE"""),"Europe,Model 3") -> Europe,Model 3 | N3: =IFERROR(__xludf.DUMMYFUNCTION("""COMPUTED_VALUE"""),"Europe,Model S/X") -> Europe,Model S/X | O3: =IFERROR(__xludf.DUMMYFUNCTION("""COMPUTED_VALUE"""),"Europe,Model Y") -> Europe,Model Y | P3: =IFERROR(__xludf.DUMMYFUNCTION("""COMPUTED_VALUE"""),"North America,Cybertruck") -> North America,Cybertruck | Q3: =IFERROR(__xludf.DUMMYFUNCTION("""COMPUTED_VALUE"""),"North America,Model 3") -> North America,Model 3 | R3: =IFERROR(__xludf.DUMMYFUNCTION("""COMPUTED_VALUE"""),"North America,Model S/X") -> North America,Model S/X | S3: =IFERROR(__xludf.DUMMYFUNCTION("""COMPUTED_VALUE"""),"North America,Model Y") -> North America,Model Y
B4: =IFERROR(__xludf.DUMMYFUNCTION("""COMPUTED_VALUE"""),2012.0) -> 2012 | E4: =IFERROR(__xludf.DUMMYFUNCTION("""COMPUTED_VALUE"""),2650.0) -> 2650 | F4: 2650 | H4: =IFERROR(__xludf.DUMMYFUNCTION("""COMPUTED_VALUE"""),2012.0) -> 2012 | R4: =IFERROR(__xludf.DUMMYFUNCTION("""COMPUTED_VALUE"""),2650.0) -> 2650 | T4: 2650
B5: =IFERROR(__xludf.DUMMYFUNCTION("""COMPUTED_VALUE"""),2013.0) -> 2013 | D5: =IFERROR(__xludf.DUMMYFUNCTION("""COMPUTED_VALUE"""),3893.0) -> 3893 | E5: =IFERROR(__xludf.DUMMYFUNCTION("""COMPUTED_VALUE"""),18584.0) -> 18584 | F5: 22477 | H5: =IFERROR(__xludf.DUMMYFUNCTION("""COMPUTED_VALUE"""),2013.0) -> 2013 | N5: =IFERROR(__xludf.DUMMYFUNCTION("""COMPUTED_VALUE"""),3893.0) -> 3893 | R5: =IFERROR(__xludf.DUMMYFUNCTION("""COMPUTED_VALUE"""),18584.0) -> 18584 | T5: 22477
B6: =IFERROR(__xludf.DUMMYFUNCTION("""COMPUTED_VALUE"""),2014.0) -> 2014 | C6: =IFERROR(__xludf.DUMMYFUNCTION("""COMPUTED_VALUE"""),4661.0) -> 4661 | D6: =IFERROR(__xludf.DUMMYFUNCTION("""COMPUTED_VALUE"""),9521.0) -> 9521 | E6: =IFERROR(__xludf.DUMMYFUNCTION("""COMPUTED_VALUE"""),17473.0) -> 17473 | F6: 31655 | H6: =IFERROR(__xludf.DUMMYFUNCTION("""COMPUTED_VALUE"""),2014.0) -> 2014 | K6: =IFERROR(__xludf.DUMMYFUNCTION("""COMPUTED_VALUE"""),4661.0) -> 4661 | N6: =IFERROR(__xludf.DUMMYFUNCTION("""COMPUTED_VALUE"""),9521.0) -> 9521 | R6: =IFERROR(__xludf.DUMMYFUNCTION("""COMPUTED_VALUE"""),17473.0) -> 17473 | T6: 31655
B7: =IFERROR(__xludf.DUMMYFUNCTION("""COMPUTED_VALUE"""),2015.0) -> 2015 | C7: =IFERROR(__xludf.DUMMYFUNCTION("""COMPUTED_VALUE"""),7155.0) -> 7155 | D7: =IFERROR(__xludf.DUMMYFUNCTION("""COMPUTED_VALUE"""),16701.0) -> 16701 | E7: =IFERROR(__xludf.DUMMYFUNCTION("""COMPUTED_VALUE"""),26802.0) -> 26802 | F7: 50658 | H7: =IFERROR(__xludf.DUMMYFUNCTION("""COMPUTED_VALUE"""),2015.0) -> 2015 | K7: =IFERROR(__xludf.DUMMYFUNCTION("""COMPUTED_VALUE"""),7155.0) -> 7155 | N7: =IFERROR(__xludf.DUMMYFUNCTION("""COMPUTED_VALUE"""),16701.0) -> 16701 | R7: =IFERROR(__xludf.DUMMYFUNCTION("""COMPUTED_VALUE"""),26802.0) -> 26802 | T7: 50658
B8: =IFERROR(__xludf.DUMMYFUNCTION("""COMPUTED_VALUE"""),2016.0) -> 2016 | C8: =IFERROR(__xludf.DUMMYFUNCTION("""COMPUTED_VALUE"""),12037.0) -> 12037 | D8: =IFERROR(__xludf.DUMMYFUNCTION("""COMPUTED_VALUE"""),16230.0) -> 16230 | E8: =IFERROR(__xludf.DUMMYFUNCTION("""COMPUTED_VALUE"""),48018.0) -> 48018 | F8: 76285 | H8: =IFERROR(__xludf.DUMMYFUNCTION("""COMPUTED_VALUE"""),2016.0) -> 2016 | K8: =IFERROR(__xludf.DUMMYFUNCTION("""COMPUTED_VALUE"""),12037.0) -> 12037 | N8: =IFERROR(__xludf.DUMMYFUNCTION("""COMPUTED_VALUE"""),16230.0) -> 16230 | R8: =IFERROR(__xludf.DUMMYFUNCTION("""COMPUTED_VALUE"""),48018.0) -> 48018 | T8: 76285
B9: =IFERROR(__xludf.DUMMYFUNCTION("""COMPUTED_VALUE"""),2017.0) -> 2017 | C9: =IFERROR(__xludf.DUMMYFUNCTION("""COMPUTED_VALUE"""),22152.0) -> 22152 | D9: =IFERROR(__xludf.DUMMYFUNCTION("""COMPUTED_VALUE"""),28279.0) -> 28279 | E9: =IFERROR(__xludf.DUMMYFUNCTION("""COMPUTED_VALUE"""),52750.0) -> 52750 | F9: 103181 | H9: =IFERROR(__xludf.DUMMYFUNCTION("""COMPUTED_VALUE"""),2017.0) -> 2017 | K9: =IFERROR(__xludf.DUMMYFUNCTION("""COMPUTED_VALUE"""),22152.0) -> 22152 | N9: =IFERROR(__xludf.DUMMYFUNCTION("""COMPUTED_VALUE"""),28279.0) -> 28279 | Q9: =IFERROR(__xludf.DUMMYFUNCTION("""COMPUTED_VALUE"""),1764.0) -> 1764 | R9: =IFERROR(__xludf.DUMMYFUNCTION("""COMPUTED_VALUE"""),50986.0) -> 50986 | T9: 103181
B10: =IFERROR(__xludf.DUMMYFUNCTION("""COMPUTED_VALUE"""),2018.0) -> 2018 | C10: =IFERROR(__xludf.DUMMYFUNCTION("""COMPUTED_VALUE"""),18408.0) -> 18408 | D10: =IFERROR(__xludf.DUMMYFUNCTION("""COMPUTED_VALUE"""),29257.0) -> 29257 | E10: =IFERROR(__xludf.DUMMYFUNCTION("""COMPUTED_VALUE"""),197841.0) -> 197841 | F10: 245506 | H10: =IFERROR(__xludf.DUMMYFUNCTION("""COMPUTED_VALUE"""),2018.0) -> 2018 | K10: =IFERROR(__xludf.DUMMYFUNCTION("""COMPUTED_VALUE"""),18408.0) -> 18408 | N10: =IFERROR(__xludf.DUMMYFUNCTION("""COMPUTED_VALUE"""),29257.0) -> 29257 | Q10: =IFERROR(__xludf.DUMMYFUNCTION("""COMPUTED_VALUE"""),146055.0) -> 146055 | R10: =IFERROR(__xludf.DUMMYFUNCTION("""COMPUTED_VALUE"""),51786.0) -> 51786 | T10: 245506
B11: =IFERROR(__xludf.DUMMYFUNCTION("""COMPUTED_VALUE"""),2019.0) -> 2019 | C11: =IFERROR(__xludf.DUMMYFUNCTION("""COMPUTED_VALUE"""),53258.0) -> 53258 | D11: =IFERROR(__xludf.DUMMYFUNCTION("""COMPUTED_VALUE"""),111119.0) -> 111119 | E11: =IFERROR(__xludf.DUMMYFUNCTION("""COMPUTED_VALUE"""),203279.0) -> 203279 | F11: 367656 | H11: =IFERROR(__xludf.DUMMYFUNCTION("""COMPUTED_VALUE"""),2019.0) -> 2019 | J11: =IFERROR(__xludf.DUMMYFUNCTION("""COMPUTED_VALUE"""),37732.0) -> 37732 | K11: =IFERROR(__xludf.DUMMYFUNCTION("""COMPUTED_VALUE"""),15526.0) -> 15526 | M11: =IFERROR(__xludf.DUMMYFUNCTION("""COMPUTED_VALUE"""),95884.0) -> 95884 | N11: =IFERROR(__xludf.DUMMYFUNCTION("""COMPUTED_VALUE"""),15235.0) -> 15235 | Q11: =IFERROR(__xludf.DUMMYFUNCTION("""COMPUTED_VALUE"""),167269.0) -> 167269 | R11: =IFERROR(__xludf.DUMMYFUNCTION("""COMPUTED_VALUE"""),36010.0) -> 36010 | T11: 367656
B12: =IFERROR(__xludf.DUMMYFUNCTION("""COMPUTED_VALUE"""),2020.0) -> 2020 | C12: =IFERROR(__xludf.DUMMYFUNCTION("""COMPUTED_VALUE"""),173659.0) -> 173659 | D12: =IFERROR(__xludf.DUMMYFUNCTION("""COMPUTED_VALUE"""),99186.0) -> 99186 | E12: =IFERROR(__xludf.DUMMYFUNCTION("""COMPUTED_VALUE"""),226802.0) -> 226802 | F12: 499647 | H12: =IFERROR(__xludf.DUMMYFUNCTION("""COMPUTED_VALUE"""),2020.0) -> 2020 | J12: =IFERROR(__xludf.DUMMYFUNCTION("""COMPUTED_VALUE"""),164412.0) -> 164412 | K12: =IFERROR(__xludf.DUMMYFUNCTION("""COMPUTED_VALUE"""),9247.0) -> 9247 | M12: =IFERROR(__xludf.DUMMYFUNCTION("""COMPUTED_VALUE"""),87976.0) -> 87976 | N12: =IFERROR(__xludf.DUMMYFUNCTION("""COMPUTED_VALUE"""),11210.0) -> 11210 | Q12: =IFERROR(__xludf.DUMMYFUNCTION("""COMPUTED_VALUE"""),103862.0) -> 103862 | R12: =IFERROR(__xludf.DUMMYFUNCTION("""COMPUTED_VALUE"""),36628.0) -> 36628 | S12: =IFERROR(__xludf.DUMMYFUNCTION("""COMPUTED_VALUE"""),86312.0) -> 86312 | T12: 499647
B13: =IFERROR(__xludf.DUMMYFUNCTION("""COMPUTED_VALUE"""),2021.0) -> 2021 | C13: =IFERROR(__xludf.DUMMYFUNCTION("""COMPUTED_VALUE"""),380497.0) -> 380497 | D13: =IFERROR(__xludf.DUMMYFUNCTION("""COMPUTED_VALUE"""),169351.0) -> 169351 | E13: =IFERROR(__xludf.DUMMYFUNCTION("""COMPUTED_VALUE"""),386374.0) -> 386374 | F13: 936222 | H13: =IFERROR(__xludf.DUMMYFUNCTION("""COMPUTED_VALUE"""),2021.0) -> 2021 | J13: =IFERROR(__xludf.DUMMYFUNCTION("""COMPUTED_VALUE"""),198141.0) -> 198141 | K13: =IFERROR(__xludf.DUMMYFUNCTION("""COMPUTED_VALUE"""),630.0) -> 630 | L13: =IFERROR(__xludf.DUMMYFUNCTION("""COMPUTED_VALUE"""),181726.0) -> 181726 | M13: =IFERROR(__xludf.DUMMYFUNCTION("""COMPUTED_VALUE"""),143664.0) -> 143664 | N13: =IFERROR(__xludf.DUMMYFUNCTION("""COMPUTED_VALUE"""),310.0) -> 310 | O13: =IFERROR(__xludf.DUMMYFUNCTION("""COMPUTED_VALUE"""),25377.0) -> 25377 | Q13: =IFERROR(__xludf.DUMMYFUNCTION("""COMPUTED_VALUE"""),168379.0) -> 168379 | R13: =IFERROR(__xludf.DUMMYFUNCTION("""COMPUTED_VALUE"""),24040.0) -> 24040 | S13: =IFERROR(__xludf.DUMMYFUNCTION("""COMPUTED_VALUE"""),193955.0) -> 193955 | T13: 936222
